
    <?xml version="1.0"?>
    <robot name="planar_arm">
      <material name="blue"><color rgba="0 0 0.8 1"/></material>
      <material name="red"><color rgba="0.8 0 0 1"/></material>

      <link name="base_link">
        <visual><geometry><cylinder length="0.1" radius="0.2"/></geometry><material name="blue"/></visual>
        <inertial><mass value="0"/><inertia ixx="0" ixy="0" ixz="0" iyy="0" iyz="0" izz="0"/></inertial>
      </link>

      <link name="link1">
        <visual>
            <geometry><box size="1.0 0.1 0.1"/></geometry>
            <origin xyz="0.5 0 0" rpy="0 0 0"/>
            <material name="red"/>
        </visual>
        <inertial><mass value="1"/><inertia ixx="0.1" ixy="0" ixz="0" iyy="0.1" iyz="0" izz="0.1"/></inertial>
      </link>

      <joint name="joint1" type="revolute">
        <parent link="base_link"/>
        <child link="link1"/>
        <axis xyz="0 0 1"/>
        <limit lower="-3.14" upper="3.14" effort="100" velocity="5"/>
        <origin xyz="0 0 0.1"/>
      </joint>

      <link name="link2">
        <visual>
            <geometry><box size="1.0 0.1 0.1"/></geometry>
            <origin xyz="0.5 0 0" rpy="0 0 0"/>
            <material name="blue"/>
        </visual>
        <inertial><mass value="1"/><inertia ixx="0.1" ixy="0" ixz="0" iyy="0.1" iyz="0" izz="0.1"/></inertial>
      </link>

      <joint name="joint2" type="revolute">
        <parent link="link1"/>
        <child link="link2"/>
        <axis xyz="0 0 1"/>
        <limit lower="-3.14" upper="3.14" effort="100" velocity="5"/>
        <origin xyz="1.0 0 0"/>
      </joint>
    </robot>
    